Workbook

Sheet Menu
B2: MAIN CONSUMPTION CONTROL CENTER
B5: 01 OCTOBER 2026 → 30 SEPTEMBER 2027 | Energy • Water • Gas • Chilled Water • LPG
B6: =HYPERLINK("#'DAILY CONSUMPTION'!A1","DAILY CONSUMPTION") | F6: =HYPERLINK("#'Utility Budget & Actual'!A1","Utility Budget & Actual") | I6: =HYPERLINK("#'LPG Dashboard'!A1","LPG Dashboard")
D10: =HYPERLINK("#'Daily Comparison'!A1","Daily Comparison") | H10: =HYPERLINK("#'Monthly Summary'!A1","Monthly Summary")
B14: MONTHLY CONSUMPTION
B16: =HYPERLINK("#'Oct 2026'!A1","Oct 2026") | E16: =HYPERLINK("#'Nov 2026'!A1","Nov 2026") | H16: =HYPERLINK("#'Dec 2026'!A1","Dec 2026") | K16: =HYPERLINK("#'Jan 2027'!A1","Jan 2027")
B19: =HYPERLINK("#'Feb 2027'!A1","Feb 2027") | E19: =HYPERLINK("#'Mar 2027'!A1","Mar 2027") | H19: =HYPERLINK("#'Apr 2027'!A1","Apr 2027") | K19: =HYPERLINK("#'May 2027'!A1","May 2027")
B22: =HYPERLINK("#'Jun 2027'!A1","Jun 2027") | E22: =HYPERLINK("#'Jul 2027'!A1","Jul 2027") | H22: =HYPERLINK("#'Aug 2027'!A1","Aug 2027") | K22: =HYPERLINK("#'Aug 2027'!A1","Aug 2027")
B25: GRAND HYATT CONSUMPTION DASHBOARD
B26: 01-Oct-2026 → 30-Sep-2027 | Daily entries | Automatic monthly and annual analysis
B27: Energy | E27: Water | H27: Gas | K27: Chilled Water
B28: ='Monthly Summary'!B20 | E28: ='Monthly Summary'!C20 | H28: ='Monthly Summary'!D20 | K28: ='Monthly Summary'!E20
B29: kWh | E29: m³ | H29: L | K29: m³

Sheet Daily Consumption
G1: INPUT RULE: Enter cumulative meter readings. Daily consumption = current reading − previous reading.
A4: ENERGY — METER READINGS
A5: Daily meter readings by area | Enter cumulative opening/closing meter readings only
A6: Meter / Area | B6: 46296 | C6: 46297 | D6: 46298 | E6: 46299 | F6: 46300 | G6: 46301 | H6: 46302 | I6: 46303 | J6: 46304 | K6: 46305 | L6: 46306 | M6: 46307 | N6: 46308 | O6: 46309 | P6: 46310 | Q6: 46311 | R6: 46312 | S6: 46313 | T6: 46314 | U6: 46315 | V6: 46316 | W6: 46317 | X6: 46318 | Y6: 46319 | Z6: 46320 | AA6: 46321 | AB6: 46322 | AC6: 46323 | AD6: 46324 | AE6: 46325 | AF6: 46326 | AG6: 46327 | AH6: 46328 | AI6: 46329 | AJ6: 46330 | AK6: 46331 | AL6: 46332 | AM6: 46333 | AN6: 46334 | AO6: 46335 | AP6: 46336 | AQ6: 46337 | AR6: 46338 | AS6: 46339 | AT6: 46340 | AU6: 46341 | AV6: 46342 | AW6: 46343 | AX6: 46344 | AY6: 46345 | AZ6: 46346 | BA6: 46347 | BB6: 46348 | BC6: 46349 | BD6: 46350 | BE6: 46351 | BF6: 46352 | BG6: 46353 | BH6: 46354 | BI6: 46355 | BJ6: 46356 | BK6: 46357 | BL6: 46358 | BM6: 46359 | BN6: 46360 | BO6: 46361 | BP6: 46362 | BQ6: 46363 | BR6: 46364 | BS6: 46365 | BT6: 46366 | BU6: 46367 | BV6: 46368 | BW6: 46369 | BX6: 46370 | BY6: 46371 | BZ6: 46372 | CA6: 46373 | CB6: 46374 | CC6: 46375 | CD6: 46376 | CE6: 46377 | CF6: 46378 | CG6: 46379 | CH6: 46380 | CI6: 46381 | CJ6: 46382 | CK6: 46383 | CL6: 46384 | CM6: 46385 | CN6: 46386 | CO6: 46387 | CP6: 46388 | CQ6: 46389 | CR6: 46390 | CS6: 46391 | CT6: 46392 | CU6: 46393 | CV6: 46394 | CW6: 46395 | CX6: 46396 | CY6: 46397 | CZ6: 46398 | DA6: 46399 | DB6: 46400 | DC6: 46401 | DD6: 46402 | DE6: 46403 | DF6: 46404 | DG6: 46405 | DH6: 46406 | DI6: 46407 | DJ6: 46408 | DK6: 46409 | DL6: 46410 | DM6: 46411 | DN6: 46412 | DO6: 46413 | DP6: 46414 | DQ6: 46415 | DR6: 46416 | DS6: 46417 | DT6: 46418 | DU6: 46419 | DV6: 46420 | DW6: 46421 | DX6: 46422 | DY6: 46423 | DZ6: 46424 | EA6: 46425 | EB6: 46426 | EC6: 46427 | ED6: 46428 | EE6: 46429 | EF6: 46430 | EG6: 46431 | EH6: 46432 | EI6: 46433 | EJ6: 46434 | EK6: 46435 | EL6: 46436 | EM6: 46437 | EN6: 46438 | EO6: 46439 | EP6: 46440 | EQ6: 46441 | ER6: 46442 | ES6: 46443 | ET6: 46444 | EU6: 46445 | EV6: 46446 | EW6: 46447 | EX6: 46448 | EY6: 46449 | EZ6: 46450 | FA6: 46451 | FB6: 46452 | FC6: 46453 | FD6: 46454 | FE6: 46455 | FF6: 46456 | FG6: 46457 | FH6: 46458 | FI6: 46459 | FJ6: 46460 | FK6: 46461 | FL6: 46462 | FM6: 46463 | FN6: 46464 | FO6: 46465 | FP6: 46466 | FQ6: 46467 | FR6: 46468 | FS6: 46469 | FT6: 46470 | FU6: 46471 | FV6: 46472 | FW6: 46473 | FX6: 46474 | FY6: 46475 | FZ6: 46476 | GA6: 46477 | GB6: 46478 | GC6: 46479 | GD6: 46480 | GE6: 46481 | GF6: 46482 | GG6: 46483 | GH6: 46484 | GI6: 46485 | GJ6: 46486 | GK6: 46487 | GL6: 46488 | GM6: 46489 | GN6: 46490 | GO6: 46491 | GP6: 46492 | GQ6: 46493 | GR6: 46494 | GS6: 46495 | GT6: 46496 | GU6: 46497 | GV6: 46498 | GW6: 46499 | GX6: 46500 | GY6: 46501 | GZ6: 46502 | HA6: 46503 | HB6: 46504 | HC6: 46505 | HD6: 46506 | HE6: 46507 | HF6: 46508 | HG6: 46509 | HH6: 46510 | HI6: 46511 | HJ6: 46512 | HK6: 46513 | HL6: 46514 | HM6: 46515 | HN6: 46516 | HO6: 46517 | HP6: 46518 | HQ6: 46519 | HR6: 46520 | HS6: 46521 | HT6: 46522 | HU6: 46523 | HV6: 46524 | HW6: 46525 | HX6: 46526 | HY6: 46527 | HZ6: 46528 | IA6: 46529 | IB6: 46530 | IC6: 46531 | ID6: 46532 | IE6: 46533 | IF6: 46534 | IG6: 46535 | IH6: 46536 | II6: 46537 | IJ6: 46538 | IK6: 46539 | IL6: 46540 | IM6: 46541 | IN6: 46542 | IO6: 46543 | IP6: 46544 | IQ6: 46545 | IR6: 46546 | IS6: 46547 | IT6: 46548 | IU6: 46549 | IV6: 46550 | IW6: 46551 | IX6: 46552 | IY6: 46553 | IZ6: 46554 | JA6: 46555 | JB6: 46556 | JC6: 46557 | JD6: 46558 | JE6: 46559 | JF6: 46560 | JG6: 46561 | JH6: 46562 | JI6: 46563 | JJ6: 46564 | JK6: 46565 | JL6: 46566 | JM6: 46567 | JN6: 46568 | JO6: 46569 | JP6: 46570 | JQ6: 46571 | JR6: 46572 | JS6: 46573 | JT6: 46574 | JU6: 46575 | JV6: 46576 | JW6: 46577 | JX6: 46578 | JY6: 46579 | JZ6: 46580 | KA6: 46581 | KB6: 46582 | KC6: 46583 | KD6: 46584 | KE6: 46585 | KF6: 46586 | KG6: 46587 | KH6: 46588 | KI6: 46589 | KJ6: 46590 | KK6: 46591 | KL6: 46592 | KM6: 46593 | KN6: 46594 | KO6: 46595 | KP6: 46596 | KQ6: 46597 | KR6: 46598 | KS6: 46599 | KT6: 46600 | KU6: 46601 | KV6: 46602 | KW6: 46603 | KX6: 46604 | KY6: 46605 | KZ6: 46606 | LA6: 46607 | LB6: 46608 | LC6: 46609 | LD6: 46610 | LE6: 46611 | LF6: 46612 | LG6: 46613 | LH6: 46614 | LI6: 46615 | LJ6: 46616 | LK6: 46617 | LL6: 46618 | LM6: 46619 | LN6: 46620 | LO6: 46621 | LP6: 46622 | LQ6: 46623 | LR6: 46624 | LS6: 46625 | LT6: 46626 | LU6: 46627 | LV6: 46628 | LW6: 46629 | LX6: 46630 | LY6: 46631 | LZ6: 46632 | MA6: 46633 | MB6: 46634 | MC6: 46635 | MD6: 46636 | ME6: 46637 | MF6: 46638 | MG6: 46639 | MH6: 46640 | MI6: 46641 | MJ6: 46642 | MK6: 46643 | ML6: 46644 | MM6: 46645 | MN6: 46646 | MO6: 46647 | MP6: 46648 | MQ6: 46649 | MR6: 46650 | MS6: 46651 | MT6: 46652 | MU6: 46653 | MV6: 46654 | MW6: 46655 | MX6: 46656 | MY6: 46657 | MZ6: 46658 | NA6: 46659 | NB6: 46660 | NC6: Annual Total
A7: Speciality Restaurant 1 - Embers | NC7: =SUM(B7:NB7)
A8: Pool Bar & Grill - Drift | NC8: =SUM(B8:NB8)
A9: Main Kitchen | NC9: =SUM(B9:NB9)
A10: Amalfi | NC10: =SUM(B10:NB10)
A11: Caffe Maude | NC11: =SUM(B11:NB11)
A12: 2:00 AM | NC12: =SUM(B12:NB12)
A13: Charcoal | NC13: =SUM(B13:NB13)
A14: El Takoy | NC14: =SUM(B14:NB14)
A15: Akira | NC15: =SUM(B15:NB15)
A16: Havanna | NC16: =SUM(B16:NB16)
A17: ENERGY DAILY CONSUMPTION (kWh) | C17: =IF(COUNT(B7:B16,C7:C16)=0,"",SUMPRODUCT(--(B7:B16<>""),--(C7:C16<>""),C7:C16-B7:B16)) | D17: =IF(COUNT(C7:C16,D7:D16)=0,"",SUMPRODUCT(--(C7:C16<>""),--(D7:D16<>""),D7:D16-C7:C16)) | E17: =IF(COUNT(D7:D16,E7:E16)=0,"",SUMPRODUCT(--(D7:D16<>""),--(E7:E16<>""),E7:E16-D7:D16)) | F17: =IF(COUNT(E7:E16,F7:F16)=0,"",SUMPRODUCT(--(E7:E16<>""),--(F7:F16<>""),F7:F16-E7:E16)) | G17: =IF(COUNT(F7:F16,G7:G16)=0,"",SUMPRODUCT(--(F7:F16<>""),--(G7:G16<>""),G7:G16-F7:F16)) | H17: =IF(COUNT(G7:G16,H7:H16)=0,"",SUMPRODUCT(--(G7:G16<>""),--(H7:H16<>""),H7:H16-G7:G16)) | I17: =IF(COUNT(H7:H16,I7:I16)=0,"",SUMPRODUCT(--(H7:H16<>""),--(I7:I16<>""),I7:I16-H7:H16)) | J17: =IF(COUNT(I7:I16,J7:J16)=0,"",SUMPRODUCT(--(I7:I16<>""),--(J7:J16<>""),J7:J16-I7:I16)) | ... NB17: =IF(COUNT(NA7:NA16,NB7:NB16)=0,"",SUMPRODUCT(--(NA7:NA16<>""),--(NB7:NB16<>""),NB7:NB16-NA7:NA16)) | NC17: =SUM(B17:NB17)
A19: WATER — METER READINGS
A20: Daily meter readings by area | Enter cumulative opening/closing meter readings only
A21: Meter / Area | B21: 46296 | C21: 46297 | D21: 46298 | E21: 46299 | F21: 46300 | G21: 46301 | H21: 46302 | I21: 46303 | J21: 46304 | K21: 46305 | L21: 46306 | M21: 46307 | N21: 46308 | O21: 46309 | P21: 46310 | Q21: 46311 | R21: 46312 | S21: 46313 | T21: 46314 | U21: 46315 | V21: 46316 | W21: 46317 | X21: 46318 | Y21: 46319 | Z21: 46320 | AA21: 46321 | AB21: 46322 | AC21: 46323 | AD21: 46324 | AE21: 46325 | AF21: 46326 | AG21: 46327 | AH21: 46328 | AI21: 46329 | AJ21: 46330 | AK21: 46331 | AL21: 46332 | AM21: 46333 | AN21: 46334 | AO21: 46335 | AP21: 46336 | AQ21: 46337 | AR21: 46338 | AS21: 46339 | AT21: 46340 | AU21: 46341 | AV21: 46342 | AW21: 46343 | AX21: 46344 | AY21: 46345 | AZ21: 46346 | BA21: 46347 | BB21: 46348 | BC21: 46349 | BD21: 46350 | BE21: 46351 | BF21: 46352 | BG21: 46353 | BH21: 46354 | BI21: 46355 | BJ21: 46356 | BK21: 46357 | BL21: 46358 | BM21: 46359 | BN21: 46360 | BO21: 46361 | BP21: 46362 | BQ21: 46363 | BR21: 46364 | BS21: 46365 | BT21: 46366 | BU21: 46367 | BV21: 46368 | BW21: 46369 | BX21: 46370 | BY21: 46371 | BZ21: 46372 | CA21: 46373 | CB21: 46374 | CC21: 46375 | CD21: 46376 | CE21: 46377 | CF21: 46378 | CG21: 46379 | CH21: 46380 | CI21: 46381 | CJ21: 46382 | CK21: 46383 | CL21: 46384 | CM21: 46385 | CN21: 46386 | CO21: 46387 | CP21: 46388 | CQ21: 46389 | CR21: 46390 | CS21: 46391 | CT21: 46392 | CU21: 46393 | CV21: 46394 | CW21: 46395 | CX21: 46396 | CY21: 46397 | CZ21: 46398 | DA21: 46399 | DB21: 46400 | DC21: 46401 | DD21: 46402 | DE21: 46403 | DF21: 46404 | DG21: 46405 | DH21: 46406 | DI21: 46407 | DJ21: 46408 | DK21: 46409 | DL21: 46410 | DM21: 46411 | DN21: 46412 | DO21: 46413 | DP21: 46414 | DQ21: 46415 | DR21: 46416 | DS21: 46417 | DT21: 46418 | DU21: 46419 | DV21: 46420 | DW21: 46421 | DX21: 46422 | DY21: 46423 | DZ21: 46424 | EA21: 46425 | EB21: 46426 | EC21: 46427 | ED21: 46428 | EE21: 46429 | EF21: 46430 | EG21: 46431 | EH21: 46432 | EI21: 46433 | EJ21: 46434 | EK21: 46435 | EL21: 46436 | EM21: 46437 | EN21: 46438 | EO21: 46439 | EP21: 46440 | EQ21: 46441 | ER21: 46442 | ES21: 46443 | ET21: 46444 | EU21: 46445 | EV21: 46446 | EW21: 46447 | EX21: 46448 | EY21: 46449 | EZ21: 46450 | FA21: 46451 | FB21: 46452 | FC21: 46453 | FD21: 46454 | FE21: 46455 | FF21: 46456 | FG21: 46457 | FH21: 46458 | FI21: 46459 | FJ21: 46460 | FK21: 46461 | FL21: 46462 | FM21: 46463 | FN21: 46464 | FO21: 46465 | FP21: 46466 | FQ21: 46467 | FR21: 46468 | FS21: 46469 | FT21: 46470 | FU21: 46471 | FV21: 46472 | FW21: 46473 | FX21: 46474 | FY21: 46475 | FZ21: 46476 | GA21: 46477 | GB21: 46478 | GC21: 46479 | GD21: 46480 | GE21: 46481 | GF21: 46482 | GG21: 46483 | GH21: 46484 | GI21: 46485 | GJ21: 46486 | GK21: 46487 | GL21: 46488 | GM21: 46489 | GN21: 46490 | GO21: 46491 | GP21: 46492 | GQ21: 46493 | GR21: 46494 | GS21: 46495 | GT21: 46496 | GU21: 46497 | GV21: 46498 | GW21: 46499 | GX21: 46500 | GY21: 46501 | GZ21: 46502 | HA21: 46503 | HB21: 46504 | HC21: 46505 | HD21: 46506 | HE21: 46507 | HF21: 46508 | HG21: 46509 | HH21: 46510 | HI21: 46511 | HJ21: 46512 | HK21: 46513 | HL21: 46514 | HM21: 46515 | HN21: 46516 | HO21: 46517 | HP21: 46518 | HQ21: 46519 | HR21: 46520 | HS21: 46521 | HT21: 46522 | HU21: 46523 | HV21: 46524 | HW21: 46525 | HX21: 46526 | HY21: 46527 | HZ21: 46528 | IA21: 46529 | IB21: 46530 | IC21: 46531 | ID21: 46532 | IE21: 46533 | IF21: 46534 | IG21: 46535 | IH21: 46536 | II21: 46537 | IJ21: 46538 | IK21: 46539 | IL21: 46540 | IM21: 46541 | IN21: 46542 | IO21: 46543 | IP21: 46544 | IQ21: 46545 | IR21: 46546 | IS21: 46547 | IT21: 46548 | IU21: 46549 | IV21: 46550 | IW21: 46551 | IX21: 46552 | IY21: 46553 | IZ21: 46554 | JA21: 46555 | JB21: 46556 | JC21: 46557 | JD21: 46558 | JE21: 46559 | JF21: 46560 | JG21: 46561 | JH21: 46562 | JI21: 46563 | JJ21: 46564 | JK21: 46565 | JL21: 46566 | JM21: 46567 | JN21: 46568 | JO21: 46569 | JP21: 46570 | JQ21: 46571 | JR21: 46572 | JS21: 46573 | JT21: 46574 | JU21: 46575 | JV21: 46576 | JW21: 46577 | JX21: 46578 | JY21: 46579 | JZ21: 46580 | KA21: 46581 | KB21: 46582 | KC21: 46583 | KD21: 46584 | KE21: 46585 | KF21: 46586 | KG21: 46587 | KH21: 46588 | KI21: 46589 | KJ21: 46590 | KK21: 46591 | KL21: 46592 | KM21: 46593 | KN21: 46594 | KO21: 46595 | KP21: 46596 | KQ21: 46597 | KR21: 46598 | KS21: 46599 | KT21: 46600 | KU21: 46601 | KV21: 46602 | KW21: 46603 | KX21: 46604 | KY21: 46605 | KZ21: 46606 | LA21: 46607 | LB21: 46608 | LC21: 46609 | LD21: 46610 | LE21: 46611 | LF21: 46612 | LG21: 46613 | LH21: 46614 | LI21: 46615 | LJ21: 46616 | LK21: 46617 | LL21: 46618 | LM21: 46619 | LN21: 46620 | LO21: 46621 | LP21: 46622 | LQ21: 46623 | LR21: 46624 | LS21: 46625 | LT21: 46626 | LU21: 46627 | LV21: 46628 | LW21: 46629 | LX21: 46630 | LY21: 46631 | LZ21: 46632 | MA21: 46633 | MB21: 46634 | MC21: 46635 | MD21: 46636 | ME21: 46637 | MF21: 46638 | MG21: 46639 | MH21: 46640 | MI21: 46641 | MJ21: 46642 | MK21: 46643 | ML21: 46644 | MM21: 46645 | MN21: 46646 | MO21: 46647 | MP21: 46648 | MQ21: 46649 | MR21: 46650 | MS21: 46651 | MT21: 46652 | MU21: 46653 | MV21: 46654 | MW21: 46655 | MX21: 46656 | MY21: 46657 | MZ21: 46658 | NA21: 46659 | NB21: 46660 | NC21: Annual Total
A22: Speciality Restaurant 1 - Embers | NC22: =SUM(B22:NB22)
A23: Pool Bar & Grill - Drift | NC23: =SUM(B23:NB23)
A24: Main Kitchen | NC24: =SUM(B24:NB24)
A25: Amalfi | NC25: =SUM(B25:NB25)
A26: Caffe Maude | NC26: =SUM(B26:NB26)
A27: 2:00 AM | NC27: =SUM(B27:NB27)
A28: Charcoal | NC28: =SUM(B28:NB28)
A29: El Takoy | NC29: =SUM(B29:NB29)
A30: Akira | NC30: =SUM(B30:NB30)
A31: Havanna | NC31: =SUM(B31:NB31)
A32: WATER DAILY CONSUMPTION (m³) | C32: =IF(COUNT(B22:B31,C22:C31)=0,"",SUMPRODUCT(--(B22:B31<>""),--(C22:C31<>""),C22:C31-B22:B31)) | D32: =IF(COUNT(C22:C31,D22:D31)=0,"",SUMPRODUCT(--(C22:C31<>""),--(D22:D31<>""),D22:D31-C22:C31)) | E32: =IF(COUNT(D22:D31,E22:E31)=0,"",SUMPRODUCT(--(D22:D31<>""),--(E22:E31<>""),E22:E31-D22:D31)) | F32: =IF(COUNT(E22:E31,F22:F31)=0,"",SUMPRODUCT(--(E22:E31<>""),--(F22:F31<>""),F22:F31-E22:E31)) | G32: =IF(COUNT(F22:F31,G22:G31)=0,"",SUMPRODUCT(--(F22:F31<>""),--(G22:G31<>""),G22:G31-F22:F31)) | H32: =IF(COUNT(G22:G31,H22:H31)=0,"",SUMPRODUCT(--(G22:G31<>""),--(H22:H31<>""),H22:H31-G22:G31)) | I32: =IF(COUNT(H22:H31,I22:I31)=0,"",SUMPRODUCT(--(H22:H31<>""),--(I22:I31<>""),I22:I31-H22:H31)) | J32: =IF(COUNT(I22:I31,J22:J31)=0,"",SUMPRODUCT(--(I22:I31<>""),--(J22:J31<>""),J22:J31-I22:I31)) | ... NB32: =IF(COUNT(NA22:NA31,NB22:NB31)=0,"",SUMPRODUCT(--(NA22:NA31<>""),--(NB22:NB31<>""),NB22:NB31-NA22:NA31)) | NC32: =SUM(B32:NB32)
A34: GAS / LPG — METER READINGS
A35: Daily meter readings by area | Enter cumulative opening/closing meter readings only
A36: Meter / Area | B36: 46296 | C36: 46297 | D36: 46298 | E36: 46299 | F36: 46300 | G36: 46301 | H36: 46302 | I36: 46303 | J36: 46304 | K36: 46305 | L36: 46306 | M36: 46307 | N36: 46308 | O36: 46309 | P36: 46310 | Q36: 46311 | R36: 46312 | S36: 46313 | T36: 46314 | U36: 46315 | V36: 46316 | W36: 46317 | X36: 46318 | Y36: 46319 | Z36: 46320 | AA36: 46321 | AB36: 46322 | AC36: 46323 | AD36: 46324 | AE36: 46325 | AF36: 46326 | AG36: 46327 | AH36: 46328 | AI36: 46329 | AJ36: 46330 | AK36: 46331 | AL36: 46332 | AM36: 46333 | AN36: 46334 | AO36: 46335 | AP36: 46336 | AQ36: 46337 | AR36: 46338 | AS36: 46339 | AT36: 46340 | AU36: 46341 | AV36: 46342 | AW36: 46343 | AX36: 46344 | AY36: 46345 | AZ36: 46346 | BA36: 46347 | BB36: 46348 | BC36: 46349 | BD36: 46350 | BE36: 46351 | BF36: 46352 | BG36: 46353 | BH36: 46354 | BI36: 46355 | BJ36: 46356 | BK36: 46357 | BL36: 46358 | BM36: 46359 | BN36: 46360 | BO36: 46361 | BP36: 46362 | BQ36: 46363 | BR36: 46364 | BS36: 46365 | BT36: 46366 | BU36: 46367 | BV36: 46368 | BW36: 46369 | BX36: 46370 | BY36: 46371 | BZ36: 46372 | CA36: 46373 | CB36: 46374 | CC36: 46375 | CD36: 46376 | CE36: 46377 | CF36: 46378 | CG36: 46379 | CH36: 46380 | CI36: 46381 | CJ36: 46382 | CK36: 46383 | CL36: 46384 | CM36: 46385 | CN36: 46386 | CO36: 46387 | CP36: 46388 | CQ36: 46389 | CR36: 46390 | CS36: 46391 | CT36: 46392 | CU36: 46393 | CV36: 46394 | CW36: 46395 | CX36: 46396 | CY36: 46397 | CZ36: 46398 | DA36: 46399 | DB36: 46400 | DC36: 46401 | DD36: 46402 | DE36: 46403 | DF36: 46404 | DG36: 46405 | DH36: 46406 | DI36: 46407 | DJ36: 46408 | DK36: 46409 | DL36: 46410 | DM36: 46411 | DN36: 46412 | DO36: 46413 | DP36: 46414 | DQ36: 46415 | DR36: 46416 | DS36: 46417 | DT36: 46418 | DU36: 46419 | DV36: 46420 | DW36: 46421 | DX36: 46422 | DY36: 46423 | DZ36: 46424 | EA36: 46425 | EB36: 46426 | EC36: 46427 | ED36: 46428 | EE36: 46429 | EF36: 46430 | EG36: 46431 | EH36: 46432 | EI36: 46433 | EJ36: 46434 | EK36: 46435 | EL36: 46436 | EM36: 46437 | EN36: 46438 | EO36: 46439 | EP36: 46440 | EQ36: 46441 | ER36: 46442 | ES36: 46443 | ET36: 46444 | EU36: 46445 | EV36: 46446 | EW36: 46447 | EX36: 46448 | EY36: 46449 | EZ36: 46450 | FA36: 46451 | FB36: 46452 | FC36: 46453 | FD36: 46454 | FE36: 46455 | FF36: 46456 | FG36: 46457 | FH36: 46458 | FI36: 46459 | FJ36: 46460 | FK36: 46461 | FL36: 46462 | FM36: 46463 | FN36: 46464 | FO36: 46465 | FP36: 46466 | FQ36: 46467 | FR36: 46468 | FS36: 46469 | FT36: 46470 | FU36: 46471 | FV36: 46472 | FW36: 46473 | FX36: 46474 | FY36: 46475 | FZ36: 46476 | GA36: 46477 | GB36: 46478 | GC36: 46479 | GD36: 46480 | GE36: 46481 | GF36: 46482 | GG36: 46483 | GH36: 46484 | GI36: 46485 | GJ36: 46486 | GK36: 46487 | GL36: 46488 | GM36: 46489 | GN36: 46490 | GO36: 46491 | GP36: 46492 | GQ36: 46493 | GR36: 46494 | GS36: 46495 | GT36: 46496 | GU36: 46497 | GV36: 46498 | GW36: 46499 | GX36: 46500 | GY36: 46501 | GZ36: 46502 | HA36: 46503 | HB36: 46504 | HC36: 46505 | HD36: 46506 | HE36: 46507 | HF36: 46508 | HG36: 46509 | HH36: 46510 | HI36: 46511 | HJ36: 46512 | HK36: 46513 | HL36: 46514 | HM36: 46515 | HN36: 46516 | HO36: 46517 | HP36: 46518 | HQ36: 46519 | HR36: 46520 | HS36: 46521 | HT36: 46522 | HU36: 46523 | HV36: 46524 | HW36: 46525 | HX36: 46526 | HY36: 46527 | HZ36: 46528 | IA36: 46529 | IB36: 46530 | IC36: 46531 | ID36: 46532 | IE36: 46533 | IF36: 46534 | IG36: 46535 | IH36: 46536 | II36: 46537 | IJ36: 46538 | IK36: 46539 | IL36: 46540 | IM36: 46541 | IN36: 46542 | IO36: 46543 | IP36: 46544 | IQ36: 46545 | IR36: 46546 | IS36: 46547 | IT36: 46548 | IU36: 46549 | IV36: 46550 | IW36: 46551 | IX36: 46552 | IY36: 46553 | IZ36: 46554 | JA36: 46555 | JB36: 46556 | JC36: 46557 | JD36: 46558 | JE36: 46559 | JF36: 46560 | JG36: 46561 | JH36: 46562 | JI36: 46563 | JJ36: 46564 | JK36: 46565 | JL36: 46566 | JM36: 46567 | JN36: 46568 | JO36: 46569 | JP36: 46570 | JQ36: 46571 | JR36: 46572 | JS36: 46573 | JT36: 46574 | JU36: 46575 | JV36: 46576 | JW36: 46577 | JX36: 46578 | JY36: 46579 | JZ36: 46580 | KA36: 46581 | KB36: 46582 | KC36: 46583 | KD36: 46584 | KE36: 46585 | KF36: 46586 | KG36: 46587 | KH36: 46588 | KI36: 46589 | KJ36: 46590 | KK36: 46591 | KL36: 46592 | KM36: 46593 | KN36: 46594 | KO36: 46595 | KP36: 46596 | KQ36: 46597 | KR36: 46598 | KS36: 46599 | KT36: 46600 | KU36: 46601 | KV36: 46602 | KW36: 46603 | KX36: 46604 | KY36: 46605 | KZ36: 46606 | LA36: 46607 | LB36: 46608 | LC36: 46609 | LD36: 46610 | LE36: 46611 | LF36: 46612 | LG36: 46613 | LH36: 46614 | LI36: 46615 | LJ36: 46616 | LK36: 46617 | LL36: 46618 | LM36: 46619 | LN36: 46620 | LO36: 46621 | LP36: 46622 | LQ36: 46623 | LR36: 46624 | LS36: 46625 | LT36: 46626 | LU36: 46627 | LV36: 46628 | LW36: 46629 | LX36: 46630 | LY36: 46631 | LZ36: 46632 | MA36: 46633 | MB36: 46634 | MC36: 46635 | MD36: 46636 | ME36: 46637 | MF36: 46638 | MG36: 46639 | MH36: 46640 | MI36: 46641 | MJ36: 46642 | MK36: 46643 | ML36: 46644 | MM36: 46645 | MN36: 46646 | MO36: 46647 | MP36: 46648 | MQ36: 46649 | MR36: 46650 | MS36: 46651 | MT36: 46652 | MU36: 46653 | MV36: 46654 | MW36: 46655 | MX36: 46656 | MY36: 46657 | MZ36: 46658 | NA36: 46659 | NB36: 46660 | NC36: Annual Total
A37: LPG Main Gas Meter | NC37: =SUM(B37:NB37)
A38: Speciality Restaurant 1 - Embers (125KW) | NC38: =SUM(B38:NB38)
A39: Pool Bar & Grill - Drift (74.5KW) | NC39: =SUM(B39:NB39)
A40: Main Kitchen (218.4KW) | NC40: =SUM(B40:NB40)
A41: Beach Bar - Amalfi (41.7KW) | NC41: =SUM(B41:NB41)
A42: Bistro Caffe - Caffe Maude (44KW) | NC42: =SUM(B42:NB42)
A43: F&B-1 - Shell & Core (54KW) | NC43: =SUM(B43:NB43)
A44: Akira Back Restaurant (124KW) | NC44: =SUM(B44:NB44)
...

Sheet Daily Comparison
A5: Daily Comparison
A7: READING DATE | D7: 46296 | E7: 46297 | F7: 46298 | G7: 46299 | H7: 46300 | I7: 46301 | J7: 46302 | K7: 46303 | L7: 46304 | M7: 46305 | N7: 46306 | O7: 46307 | P7: 46308 | Q7: 46309 | R7: 46310 | S7: 46311 | T7: 46312 | U7: 46313 | V7: 46314 | W7: 46315 | X7: 46316 | Y7: 46317 | Z7: 46318 | AA7: 46319 | AB7: 46320 | AC7: 46321 | AD7: 46322 | AE7: 46323 | AF7: 46324 | AG7: 46325 | AH7: 46326 | AI7: 46327 | AJ7: 46328 | AK7: 46329 | AL7: 46330 | AM7: 46331 | AN7: 46332 | AO7: 46333 | AP7: 46334 | AQ7: 46335 | AR7: 46336 | AS7: 46337 | AT7: 46338 | AU7: 46339 | AV7: 46340 | AW7: 46341 | AX7: 46342 | AY7: 46343 | AZ7: 46344 | BA7: 46345 | BB7: 46346 | BC7: 46347 | BD7: 46348 | BE7: 46349 | BF7: 46350 | BG7: 46351 | BH7: 46352 | BI7: 46353 | BJ7: 46354 | BK7: 46355 | BL7: 46356 | BM7: 46357 | BN7: 46358 | BO7: 46359 | BP7: 46360 | BQ7: 46361 | BR7: 46362 | BS7: 46363 | BT7: 46364 | BU7: 46365 | BV7: 46366 | BW7: 46367 | BX7: 46368 | BY7: 46369 | BZ7: 46370 | CA7: 46371 | CB7: 46372 | CC7: 46373 | CD7: 46374 | CE7: 46375 | CF7: 46376 | CG7: 46377 | CH7: 46378 | CI7: 46379 | CJ7: 46380 | CK7: 46381 | CL7: 46382 | CM7: 46383 | CN7: 46384 | CO7: 46385 | CP7: 46386 | CQ7: 46387 | CR7: 46388 | CS7: 46389 | CT7: 46390 | CU7: 46391 | CV7: 46392 | CW7: 46393 | CX7: 46394 | CY7: 46395 | CZ7: 46396 | DA7: 46397 | DB7: 46398 | DC7: 46399 | DD7: 46400 | DE7: 46401 | DF7: 46402 | DG7: 46403 | DH7: 46404 | DI7: 46405 | DJ7: 46406 | DK7: 46407 | DL7: 46408 | DM7: 46409 | DN7: 46410 | DO7: 46411 | DP7: 46412 | DQ7: 46413 | DR7: 46414 | DS7: 46415 | DT7: 46416 | DU7: 46417 | DV7: 46418 | DW7: 46419 | DX7: 46420 | DY7: 46421 | DZ7: 46422 | EA7: 46423 | EB7: 46424 | EC7: 46425 | ED7: 46426 | EE7: 46427 | EF7: 46428 | EG7: 46429 | EH7: 46430 | EI7: 46431 | EJ7: 46432 | EK7: 46433 | EL7: 46434 | EM7: 46435 | EN7: 46436 | EO7: 46437 | EP7: 46438 | EQ7: 46439 | ER7: 46440 | ES7: 46441 | ET7: 46442 | EU7: 46443 | EV7: 46444 | EW7: 46445 | EX7: 46446 | EY7: 46447 | EZ7: 46448 | FA7: 46449 | FB7: 46450 | FC7: 46451 | FD7: 46452 | FE7: 46453 | FF7: 46454 | FG7: 46455 | FH7: 46456 | FI7: 46457 | FJ7: 46458 | FK7: 46459 | FL7: 46460 | FM7: 46461 | FN7: 46462 | FO7: 46463 | FP7: 46464 | FQ7: 46465 | FR7: 46466 | FS7: 46467 | FT7: 46468 | FU7: 46469 | FV7: 46470 | FW7: 46471 | FX7: 46472 | FY7: 46473 | FZ7: 46474 | GA7: 46475 | GB7: 46476 | GC7: 46477 | GD7: 46478 | GE7: 46479 | GF7: 46480 | GG7: 46481 | GH7: 46482 | GI7: 46483 | GJ7: 46484 | GK7: 46485 | GL7: 46486 | GM7: 46487 | GN7: 46488 | GO7: 46489 | GP7: 46490 | GQ7: 46491 | GR7: 46492 | GS7: 46493 | GT7: 46494 | GU7: 46495 | GV7: 46496 | GW7: 46497 | GX7: 46498 | GY7: 46499 | GZ7: 46500 | HA7: 46501 | HB7: 46502 | HC7: 46503 | HD7: 46504 | HE7: 46505 | HF7: 46506 | HG7: 46507 | HH7: 46508 | HI7: 46509 | HJ7: 46510 | HK7: 46511 | HL7: 46512 | HM7: 46513 | HN7: 46514 | HO7: 46515 | HP7: 46516 | HQ7: 46517 | HR7: 46518 | HS7: 46519 | HT7: 46520 | HU7: 46521 | HV7: 46522 | HW7: 46523 | HX7: 46524 | HY7: 46525 | HZ7: 46526 | IA7: 46527 | IB7: 46528 | IC7: 46529 | ID7: 46530 | IE7: 46531 | IF7: 46532 | IG7: 46533 | IH7: 46534 | II7: 46535 | IJ7: 46536 | IK7: 46537 | IL7: 46538 | IM7: 46539 | IN7: 46540 | IO7: 46541 | IP7: 46542 | IQ7: 46543 | IR7: 46544 | IS7: 46545 | IT7: 46546 | IU7: 46547 | IV7: 46548 | IW7: 46549 | IX7: 46550 | IY7: 46551 | IZ7: 46552 | JA7: 46553 | JB7: 46554 | JC7: 46555 | JD7: 46556 | JE7: 46557 | JF7: 46558 | JG7: 46559 | JH7: 46560 | JI7: 46561 | JJ7: 46562 | JK7: 46563 | JL7: 46564 | JM7: 46565 | JN7: 46566 | JO7: 46567 | JP7: 46568 | JQ7: 46569 | JR7: 46570 | JS7: 46571 | JT7: 46572 | JU7: 46573 | JV7: 46574 | JW7: 46575 | JX7: 46576 | JY7: 46577 | JZ7: 46578 | KA7: 46579 | KB7: 46580 | KC7: 46581 | KD7: 46582 | KE7: 46583 | KF7: 46584 | KG7: 46585 | KH7: 46586 | KI7: 46587 | KJ7: 46588 | KK7: 46589 | KL7: 46590 | KM7: 46591 | KN7: 46592 | KO7: 46593 | KP7: 46594 | KQ7: 46595 | KR7: 46596 | KS7: 46597 | KT7: 46598 | KU7: 46599 | KV7: 46600 | KW7: 46601 | KX7: 46602 | KY7: 46603 | KZ7: 46604 | LA7: 46605 | LB7: 46606 | LC7: 46607 | LD7: 46608 | LE7: 46609 | LF7: 46610 | LG7: 46611 | LH7: 46612 | LI7: 46613 | LJ7: 46614 | LK7: 46615 | LL7: 46616 | LM7: 46617 | LN7: 46618 | LO7: 46619 | LP7: 46620 | LQ7: 46621 | LR7: 46622 | LS7: 46623 | LT7: 46624 | LU7: 46625 | LV7: 46626 | LW7: 46627 | LX7: 46628 | LY7: 46629 | LZ7: 46630 | MA7: 46631 | MB7: 46632 | MC7: 46633 | MD7: 46634 | ME7: 46635 | MF7: 46636 | MG7: 46637 | MH7: 46638 | MI7: 46639 | MJ7: 46640 | MK7: 46641 | ML7: 46642 | MM7: 46643 | MN7: 46644 | MO7: 46645 | MP7: 46646 | MQ7: 46647 | MR7: 46648 | MS7: 46649 | MT7: 46650 | MU7: 46651 | MV7: 46652 | MW7: 46653 | MX7: 46654 | MY7: 46655 | MZ7: 46656 | NA7: 46657 | NB7: 46658 | NC7: 46659 | ND7: 46660 | NE7: 46661
A8: ENERGY CONSUMPTION
A9: Daily Consumption | C9: kWh | D9: ='Daily Consumption'!B17 | E9: ='Daily Consumption'!C17 | F9: ='Daily Consumption'!D17 | G9: ='Daily Consumption'!E17 | H9: ='Daily Consumption'!F17 | I9: ='Daily Consumption'!G17 | J9: ='Daily Consumption'!H17 | K9: ='Daily Consumption'!I17 | ... ND9: ='Daily Consumption'!NB17 | NE9: ='Daily Consumption'!NE17
A10: Daily Consumption N-1 | C10: kWh | E10: ='Daily Consumption'!B17 | F10: ='Daily Consumption'!C17 | G10: ='Daily Consumption'!D17 | H10: ='Daily Consumption'!E17 | I10: ='Daily Consumption'!F17 | J10: ='Daily Consumption'!G17 | K10: ='Daily Consumption'!H17 | L10: ='Daily Consumption'!I17 | ... ND10: ='Daily Consumption'!NA17 | NE10: ='Daily Consumption'!ND17
A11: WATER CONSUMPTION
A12: Daily Consumption | C12: m³ | D12: ='Daily Consumption'!B32 | E12: ='Daily Consumption'!C32 | F12: ='Daily Consumption'!D32 | G12: ='Daily Consumption'!E32 | H12: ='Daily Consumption'!F32 | I12: ='Daily Consumption'!G32 | J12: ='Daily Consumption'!H32 | K12: ='Daily Consumption'!I32 | ... ND12: ='Daily Consumption'!NB32 | NE12: ='Daily Consumption'!NE32
A13: Daily Consumption N-1 | C13: m³ | E13: ='Daily Consumption'!B32 | F13: ='Daily Consumption'!C32 | G13: ='Daily Consumption'!D32 | H13: ='Daily Consumption'!E32 | I13: ='Daily Consumption'!F32 | J13: ='Daily Consumption'!G32 | K13: ='Daily Consumption'!H32 | L13: ='Daily Consumption'!I32 | ... ND13: ='Daily Consumption'!NA32 | NE13: ='Daily Consumption'!ND32
A14: GAS CONSUMPTION
A15: Daily Consumption | C15: L | D15: ='Daily Consumption'!B46 | E15: ='Daily Consumption'!C46 | F15: ='Daily Consumption'!D46 | G15: ='Daily Consumption'!E46 | H15: ='Daily Consumption'!F46 | I15: ='Daily Consumption'!G46 | J15: ='Daily Consumption'!H46 | K15: ='Daily Consumption'!I46 | ... ND15: ='Daily Consumption'!NB46 | NE15: ='Daily Consumption'!NE46
A16: Daily Consumption N-1 | C16: L | E16: ='Daily Consumption'!B46 | F16: ='Daily Consumption'!C46 | G16: ='Daily Consumption'!D46 | H16: ='Daily Consumption'!E46 | I16: ='Daily Consumption'!F46 | J16: ='Daily Consumption'!G46 | K16: ='Daily Consumption'!H46 | L16: ='Daily Consumption'!I46 | ... ND16: ='Daily Consumption'!NA46 | NE16: ='Daily Consumption'!ND46
A17: CLIMATE DATA
A18: Average Daily Temperature N | C18: C° | D18: ='Daily Consumption'!B110 | E18: ='Daily Consumption'!C110 | F18: ='Daily Consumption'!D110 | G18: ='Daily Consumption'!E110 | H18: ='Daily Consumption'!F110 | I18: ='Daily Consumption'!G110 | J18: ='Daily Consumption'!H110 | K18: ='Daily Consumption'!I110 | ... ND18: ='Daily Consumption'!NB110
A19: Average Daily Temperature N-1 | C19: C° | E19: ='Daily Consumption'!B110 | F19: ='Daily Consumption'!C110 | G19: ='Daily Consumption'!D110 | H19: ='Daily Consumption'!E110 | I19: ='Daily Consumption'!F110 | J19: ='Daily Consumption'!G110 | K19: ='Daily Consumption'!H110 | L19: ='Daily Consumption'!I110 | ... ND19: ='Daily Consumption'!NA110
A20: OCCUPANCY DATA
A21: N | B21: Occupancy Rate | D21: ='Daily Consumption'!B112 | E21: ='Daily Consumption'!C112 | F21: ='Daily Consumption'!D112 | G21: ='Daily Consumption'!E112 | H21: ='Daily Consumption'!F112 | I21: ='Daily Consumption'!G112 | J21: ='Daily Consumption'!H112 | K21: ='Daily Consumption'!I112 | ... ND21: ='Daily Consumption'!NB112
B22: Occupied Rooms | D22: ='Daily Consumption'!B113 | E22: ='Daily Consumption'!C113 | F22: ='Daily Consumption'!D113 | G22: ='Daily Consumption'!E113 | H22: ='Daily Consumption'!F113 | I22: ='Daily Consumption'!G113 | J22: ='Daily Consumption'!H113 | K22: ='Daily Consumption'!I113 | ... ND22: ='Daily Consumption'!NB113
B23: Hotel Guests | D23: ='Daily Consumption'!B114 | E23: ='Daily Consumption'!C114 | F23: ='Daily Consumption'!D114 | G23: ='Daily Consumption'!E114 | H23: ='Daily Consumption'!F114 | I23: ='Daily Consumption'!G114 | J23: ='Daily Consumption'!H114 | K23: ='Daily Consumption'!I114 | ... ND23: ='Daily Consumption'!NB114
A24: ENERGY COST
A25: N | B25: Electricity | C25: SAR
A26: N - 1
A27: N | B27: Water | C27: SAR
A28: N - 1
A29: N | B29: Gas | C29: SAR
A30: N - 1
A31: N | B31: Total Energy Cost | C31: SAR
A32: N - 1
A33: N | B33: Energy Cost per Guest | C33: SAR
A34: N - 1
A35: N | B35: Energy Cost per Room | C35: SAR
A37: MONTHLY CONSUMPTION SUMMARY
A38: Reporting Cycle | B38: 2026-27 | C38: xxxx
A39: Oct 2026 | B39: =SUM('Oct 2026'!B8:B38)+SUM('Oct 2026'!C8:C38)+SUM('Oct 2026'!D8:D38)+SUM('Oct 2026'!E8:E38) | C39: 0
A40: Nov 2026 | B40: =SUM('Nov 2026'!B8:B37)+SUM('Nov 2026'!C8:C37)+SUM('Nov 2026'!D8:D37)+SUM('Nov 2026'!E8:E37) | C40: 0
A41: Dec 2026 | B41: =SUM('Dec 2026'!B8:B38)+SUM('Dec 2026'!C8:C38)+SUM('Dec 2026'!D8:D38)+SUM('Dec 2026'!E8:E38) | C41: 0
A42: Jan 2027 | B42: =SUM('Jan 2027'!B8:B38)+SUM('Jan 2027'!C8:C38)+SUM('Jan 2027'!D8:D38)+SUM('Jan 2027'!E8:E38) | C42: 0
A43: Feb 2027 | B43: =SUM('Feb 2027'!B8:B35)+SUM('Feb 2027'!C8:C35)+SUM('Feb 2027'!D8:D35)+SUM('Feb 2027'!E8:E35) | C43: 0
A44: Mar 2027 | B44: =SUM('Mar 2027'!B8:B38)+SUM('Mar 2027'!C8:C38)+SUM('Mar 2027'!D8:D38)+SUM('Mar 2027'!E8:E38) | C44: 0
A45: Apr 2027 | B45: =SUM('Apr 2027'!B8:B37)+SUM('Apr 2027'!C8:C37)+SUM('Apr 2027'!D8:D37)+SUM('Apr 2027'!E8:E37) | C45: 0
A46: May 2027 | B46: =SUM('May 2027'!B8:B38)+SUM('May 2027'!C8:C38)+SUM('May 2027'!D8:D38)+SUM('May 2027'!E8:E38) | C46: 0
...

Sheet Utility Budget & Actual
B5: UTILITY BUDGET 2026-27
B6: OCTOBER | C6: NOVEMBER | D6: DECEMBER | E6: JANUARY | F6: FEBRUARY | G6: MARCH | H6: APRIL | I6: MAY | J6: JUNE | K6: JULY | L6: AUGUST | M6: SEPTEMBER | N6: TOTAL
A7: Rooms Sold | N7: =SUM(B7:M7)
A8: Occupancy Rate | N8: =SUM(B8:M8)
A9: Guests | N9: =SUM(B9:M9)
A11: Gas | N11: =SUM(B11:M11)
A12: Electricity | N12: =SUM(B12:M12)
A13: Water | N13: =SUM(B13:M13)
A14: Total | B14: =SUM(B11:B13) | C14: =SUM(C11:C13) | D14: =SUM(D11:D13) | E14: =SUM(E11:E13) | F14: =SUM(F11:F13) | G14: =SUM(G11:G13) | H14: =SUM(H11:H13) | I14: =SUM(I11:I13) | ... M14: =SUM(M11:M13) | N14: =SUM(B14:M14)
B16: ACTUAL UTILITY CONSUMPTION 2026-27
B17: OCTOBER | C17: NOVEMBER | D17: DECEMBER | E17: JANUARY | F17: FEBRUARY | G17: MARCH | H17: APRIL | I17: MAY | J17: JUNE | K17: JULY | L17: AUGUST | M17: SEPTEMBER | N17: TOTAL
A18: Rooms Sold | B18: =SUMPRODUCT(('Daily Consumption'!$B$6:$NB$6>=DATE(2026,10,1))*('Daily Consumption'!$B$6:$NB$6<=DATE(2026,10,31))*'Daily Consumption'!$B$113:$NB$113) | C18: =SUMPRODUCT(('Daily Consumption'!$B$6:$NB$6>=DATE(2026,11,1))*('Daily Consumption'!$B$6:$NB$6<=DATE(2026,11,30))*'Daily Consumption'!$B$113:$NB$113) | D18: =SUMPRODUCT(('Daily Consumption'!$B$6:$NB$6>=DATE(2026,12,1))*('Daily Consumption'!$B$6:$NB$6<=DATE(2026,12,31))*'Daily Consumption'!$B$113:$NB$113) | E18: =SUMPRODUCT(('Daily Consumption'!$B$6:$NB$6>=DATE(2027,1,1))*('Daily Consumption'!$B$6:$NB$6<=DATE(2027,1,31))*'Daily Consumption'!$B$113:$NB$113) | F18: =SUMPRODUCT(('Daily Consumption'!$B$6:$NB$6>=DATE(2027,2,1))*('Daily Consumption'!$B$6:$NB$6<=DATE(2027,2,28))*'Daily Consumption'!$B$113:$NB$113) | G18: =SUMPRODUCT(('Daily Consumption'!$B$6:$NB$6>=DATE(2027,3,1))*('Daily Consumption'!$B$6:$NB$6<=DATE(2027,3,31))*'Daily Consumption'!$B$113:$NB$113) | H18: =SUMPRODUCT(('Daily Consumption'!$B$6:$NB$6>=DATE(2027,4,1))*('Daily Consumption'!$B$6:$NB$6<=DATE(2027,4,30))*'Daily Consumption'!$B$113:$NB$113) | I18: =SUMPRODUCT(('Daily Consumption'!$B$6:$NB$6>=DATE(2027,5,1))*('Daily Consumption'!$B$6:$NB$6<=DATE(2027,5,31))*'Daily Consumption'!$B$113:$NB$113) | J18: =SUMPRODUCT(('Daily Consumption'!$B$6:$NB$6>=DATE(2027,6,1))*('Daily Consumption'!$B$6:$NB$6<=DATE(2027,6,30))*'Daily Consumption'!$B$113:$NB$113) | K18: =SUMPRODUCT(('Daily Consumption'!$B$6:$NB$6>=DATE(2027,7,1))*('Daily Consumption'!$B$6:$NB$6<=DATE(2027,7,31))*'Daily Consumption'!$B$113:$NB$113) | L18: =SUMPRODUCT(('Daily Consumption'!$B$6:$NB$6>=DATE(2027,8,1))*('Daily Consumption'!$B$6:$NB$6<=DATE(2027,8,31))*'Daily Consumption'!$B$113:$NB$113) | M18: =SUMPRODUCT(('Daily Consumption'!$B$6:$NB$6>=DATE(2027,9,1))*('Daily Consumption'!$B$6:$NB$6<=DATE(2027,9,30))*'Daily Consumption'!$B$113:$NB$113) | N18: =SUM(B18:M18)
A19: Occupancy Rate | B19: =IFERROR(AVERAGEIFS('Daily Consumption'!$B$112:$NB$112,'Daily Consumption'!$B$6:$NB$6,">="&DATE(2026,10,1),'Daily Consumption'!$B$6:$NB$6,"<="&DATE(2026,10,31)),"") | C19: =IFERROR(AVERAGEIFS('Daily Consumption'!$B$112:$NB$112,'Daily Consumption'!$B$6:$NB$6,">="&DATE(2026,11,1),'Daily Consumption'!$B$6:$NB$6,"<="&DATE(2026,11,30)),"") | D19: =IFERROR(AVERAGEIFS('Daily Consumption'!$B$112:$NB$112,'Daily Consumption'!$B$6:$NB$6,">="&DATE(2026,12,1),'Daily Consumption'!$B$6:$NB$6,"<="&DATE(2026,12,31)),"") | E19: =IFERROR(AVERAGEIFS('Daily Consumption'!$B$112:$NB$112,'Daily Consumption'!$B$6:$NB$6,">="&DATE(2027,1,1),'Daily Consumption'!$B$6:$NB$6,"<="&DATE(2027,1,31)),"") | F19: =IFERROR(AVERAGEIFS('Daily Consumption'!$B$112:$NB$112,'Daily Consumption'!$B$6:$NB$6,">="&DATE(2027,2,1),'Daily Consumption'!$B$6:$NB$6,"<="&DATE(2027,2,28)),"") | G19: =IFERROR(AVERAGEIFS('Daily Consumption'!$B$112:$NB$112,'Daily Consumption'!$B$6:$NB$6,">="&DATE(2027,3,1),'Daily Consumption'!$B$6:$NB$6,"<="&DATE(2027,3,31)),"") | H19: =IFERROR(AVERAGEIFS('Daily Consumption'!$B$112:$NB$112,'Daily Consumption'!$B$6:$NB$6,">="&DATE(2027,4,1),'Daily Consumption'!$B$6:$NB$6,"<="&DATE(2027,4,30)),"") | I19: =IFERROR(AVERAGEIFS('Daily Consumption'!$B$112:$NB$112,'Daily Consumption'!$B$6:$NB$6,">="&DATE(2027,5,1),'Daily Consumption'!$B$6:$NB$6,"<="&DATE(2027,5,31)),"") | J19: =IFERROR(AVERAGEIFS('Daily Consumption'!$B$112:$NB$112,'Daily Consumption'!$B$6:$NB$6,">="&DATE(2027,6,1),'Daily Consumption'!$B$6:$NB$6,"<="&DATE(2027,6,30)),"") | K19: =IFERROR(AVERAGEIFS('Daily Consumption'!$B$112:$NB$112,'Daily Consumption'!$B$6:$NB$6,">="&DATE(2027,7,1),'Daily Consumption'!$B$6:$NB$6,"<="&DATE(2027,7,31)),"") | L19: =IFERROR(AVERAGEIFS('Daily Consumption'!$B$112:$NB$112,'Daily Consumption'!$B$6:$NB$6,">="&DATE(2027,8,1),'Daily Consumption'!$B$6:$NB$6,"<="&DATE(2027,8,31)),"") | M19: =IFERROR(AVERAGEIFS('Daily Consumption'!$B$112:$NB$112,'Daily Consumption'!$B$6:$NB$6,">="&DATE(2027,9,1),'Daily Consumption'!$B$6:$NB$6,"<="&DATE(2027,9,30)),"") | N19: =IFERROR(AVERAGE(B19:M19),"")
A20: Guests | B20: =SUMPRODUCT(('Daily Consumption'!$B$6:$NB$6>=DATE(2026,10,1))*('Daily Consumption'!$B$6:$NB$6<=DATE(2026,10,31))*'Daily Consumption'!$B$114:$NB$114) | C20: =SUMPRODUCT(('Daily Consumption'!$B$6:$NB$6>=DATE(2026,11,1))*('Daily Consumption'!$B$6:$NB$6<=DATE(2026,11,30))*'Daily Consumption'!$B$114:$NB$114) | D20: =SUMPRODUCT(('Daily Consumption'!$B$6:$NB$6>=DATE(2026,12,1))*('Daily Consumption'!$B$6:$NB$6<=DATE(2026,12,31))*'Daily Consumption'!$B$114:$NB$114) | E20: =SUMPRODUCT(('Daily Consumption'!$B$6:$NB$6>=DATE(2027,1,1))*('Daily Consumption'!$B$6:$NB$6<=DATE(2027,1,31))*'Daily Consumption'!$B$114:$NB$114) | F20: =SUMPRODUCT(('Daily Consumption'!$B$6:$NB$6>=DATE(2027,2,1))*('Daily Consumption'!$B$6:$NB$6<=DATE(2027,2,28))*'Daily Consumption'!$B$114:$NB$114) | G20: =SUMPRODUCT(('Daily Consumption'!$B$6:$NB$6>=DATE(2027,3,1))*('Daily Consumption'!$B$6:$NB$6<=DATE(2027,3,31))*'Daily Consumption'!$B$114:$NB$114) | H20: =SUMPRODUCT(('Daily Consumption'!$B$6:$NB$6>=DATE(2027,4,1))*('Daily Consumption'!$B$6:$NB$6<=DATE(2027,4,30))*'Daily Consumption'!$B$114:$NB$114) | I20: =SUMPRODUCT(('Daily Consumption'!$B$6:$NB$6>=DATE(2027,5,1))*('Daily Consumption'!$B$6:$NB$6<=DATE(2027,5,31))*'Daily Consumption'!$B$114:$NB$114) | J20: =SUMPRODUCT(('Daily Consumption'!$B$6:$NB$6>=DATE(2027,6,1))*('Daily Consumption'!$B$6:$NB$6<=DATE(2027,6,30))*'Daily Consumption'!$B$114:$NB$114) | K20: =SUMPRODUCT(('Daily Consumption'!$B$6:$NB$6>=DATE(2027,7,1))*('Daily Consumption'!$B$6:$NB$6<=DATE(2027,7,31))*'Daily Consumption'!$B$114:$NB$114) | L20: =SUMPRODUCT(('Daily Consumption'!$B$6:$NB$6>=DATE(2027,8,1))*('Daily Consumption'!$B$6:$NB$6<=DATE(2027,8,31))*'Daily Consumption'!$B$114:$NB$114) | M20: =SUMPRODUCT(('Daily Consumption'!$B$6:$NB$6>=DATE(2027,9,1))*('Daily Consumption'!$B$6:$NB$6<=DATE(2027,9,30))*'Daily Consumption'!$B$114:$NB$114) | N20: =SUM(B20:M20)
A22: Gas | B22: =SUM('Oct 2026'!D8:D38) | C22: =SUM('Nov 2026'!D8:D37) | D22: =SUM('Dec 2026'!D8:D38) | E22: =SUM('Jan 2027'!D8:D38) | F22: =SUM('Feb 2027'!D8:D35) | G22: =SUM('Mar 2027'!D8:D38) | H22: =SUM('Apr 2027'!D8:D37) | I22: =SUM('May 2027'!D8:D38) | J22: =SUM('Jun 2027'!D8:D37) | K22: =SUM('Jul 2027'!D8:D38) | L22: =SUM('Aug 2027'!D8:D38) | M22: =SUM('Sep 2027'!D8:D37) | N22: =SUM(B22:M22)
A23: Electricity | B23: =SUM('Oct 2026'!B8:B38) | C23: =SUM('Nov 2026'!B8:B37) | D23: =SUM('Dec 2026'!B8:B38) | E23: =SUM('Jan 2027'!B8:B38) | F23: =SUM('Feb 2027'!B8:B35) | G23: =SUM('Mar 2027'!B8:B38) | H23: =SUM('Apr 2027'!B8:B37) | I23: =SUM('May 2027'!B8:B38) | J23: =SUM('Jun 2027'!B8:B37) | K23: =SUM('Jul 2027'!B8:B38) | L23: =SUM('Aug 2027'!B8:B38) | M23: =SUM('Sep 2027'!B8:B37) | N23: =SUM(B23:M23)
A24: Water | B24: =SUM('Oct 2026'!C8:C38) | C24: =SUM('Nov 2026'!C8:C37) | D24: =SUM('Dec 2026'!C8:C38) | E24: =SUM('Jan 2027'!C8:C38) | F24: =SUM('Feb 2027'!C8:C35) | G24: =SUM('Mar 2027'!C8:C38) | H24: =SUM('Apr 2027'!C8:C37) | I24: =SUM('May 2027'!C8:C38) | J24: =SUM('Jun 2027'!C8:C37) | K24: =SUM('Jul 2027'!C8:C38) | L24: =SUM('Aug 2027'!C8:C38) | M24: =SUM('Sep 2027'!C8:C37) | N24: =SUM(B24:M24)
A25: Total | B25: =SUM(B22:B24) | C25: =SUM(C22:C24) | D25: =SUM(D22:D24) | E25: =SUM(E22:E24) | F25: =SUM(F22:F24) | G25: =SUM(G22:G24) | H25: =SUM(H22:H24) | I25: =SUM(I22:I24) | ... M25: =SUM(M22:M24) | N25: =SUM(B25:M25)
B28: PREVIOUS PERIOD REFERENCE
B29: OCTOBER | C29: NOVEMBER | D29: DECEMBER | E29: JANUARY | F29: FEBRUARY | G29: MARCH | H29: APRIL | I29: MAY | J29: JUNE | K29: JULY | L29: AUGUST | M29: SEPTEMBER | N29: TOTAL
A30: Rooms Sold
A31: Occupancy Rate
A32: Guests
A34: Gas
A35: Electricity
A36: Water
A37: Total

Sheet Monthly Summary
A5: MONTHLY CONSUMPTION SUMMARY
A6: Automatic 12-month totals | 01-Oct-2026 to 30-Sep-2027
A7: Month | B7: Energy Consumption | C7: Water Consumption | D7: Gas Consumption | E7: Chilled Water Consumption | F7: All Utilities
A8: 46296 | B8: =SUM('Oct 2026'!B8:B38) | C8: =SUM('Oct 2026'!C8:C38) | D8: =SUM('Oct 2026'!D8:D38) | E8: =SUM('Oct 2026'!E8:E38) | F8: =SUM(B8:E8)
A9: 46327 | B9: =SUM('Nov 2026'!B8:B37) | C9: =SUM('Nov 2026'!C8:C37) | D9: =SUM('Nov 2026'!D8:D37) | E9: =SUM('Nov 2026'!E8:E37) | F9: =SUM(B9:E9) | G9: Dec 2026 | H9: Jan 2027 | I9: Feb 2027 | J9: Mar 2027 | K9: Apr 2027 | L9: May 2027 | M9: Jun 2027 | N9: Jul 2027 | O9: Aug 2027 | P9: Sep 2027
A10: 46357 | B10: =SUM('Dec 2026'!B8:B38) | C10: =SUM('Dec 2026'!C8:C38) | D10: =SUM('Dec 2026'!D8:D38) | E10: =SUM('Dec 2026'!E8:E38) | F10: =SUM(B10:E10)
A11: 46388 | B11: =SUM('Jan 2027'!B8:B38) | C11: =SUM('Jan 2027'!C8:C38) | D11: =SUM('Jan 2027'!D8:D38) | E11: =SUM('Jan 2027'!E8:E38) | F11: =SUM(B11:E11)
A12: 46419 | B12: =SUM('Feb 2027'!B8:B35) | C12: =SUM('Feb 2027'!C8:C35) | D12: =SUM('Feb 2027'!D8:D35) | E12: =SUM('Feb 2027'!E8:E35) | F12: =SUM(B12:E12)
A13: 46447 | B13: =SUM('Mar 2027'!B8:B38) | C13: =SUM('Mar 2027'!C8:C38) | D13: =SUM('Mar 2027'!D8:D38) | E13: =SUM('Mar 2027'!E8:E38) | F13: =SUM(B13:E13)
A14: 46478 | B14: =SUM('Apr 2027'!B8:B37) | C14: =SUM('Apr 2027'!C8:C37) | D14: =SUM('Apr 2027'!D8:D37) | E14: =SUM('Apr 2027'!E8:E37) | F14: =SUM(B14:E14)
A15: 46508 | B15: =SUM('May 2027'!B8:B38) | C15: =SUM('May 2027'!C8:C38) | D15: =SUM('May 2027'!D8:D38) | E15: =SUM('May 2027'!E8:E38) | F15: =SUM(B15:E15)
A16: 46539 | B16: =SUM('Jun 2027'!B8:B37) | C16: =SUM('Jun 2027'!C8:C37) | D16: =SUM('Jun 2027'!D8:D37) | E16: =SUM('Jun 2027'!E8:E37) | F16: =SUM(B16:E16)
A17: 46569 | B17: =SUM('Jul 2027'!B8:B38) | C17: =SUM('Jul 2027'!C8:C38) | D17: =SUM('Jul 2027'!D8:D38) | E17: =SUM('Jul 2027'!E8:E38) | F17: =SUM(B17:E17)
A18: 46600 | B18: =SUM('Aug 2027'!B8:B38) | C18: =SUM('Aug 2027'!C8:C38) | D18: =SUM('Aug 2027'!D8:D38) | E18: =SUM('Aug 2027'!E8:E38) | F18: =SUM(B18:E18)
A19: 46631 | B19: =SUM('Sep 2027'!B8:B37) | C19: =SUM('Sep 2027'!C8:C37) | D19: =SUM('Sep 2027'!D8:D37) | E19: =SUM('Sep 2027'!E8:E37) | F19: =SUM(B19:E19)
A20: ANNUAL TOTAL | B20: =SUM(B8:B19) | C20: =SUM(C8:C19) | D20: =SUM(D8:D19) | E20: =SUM(E8:E19) | F20: =SUM(F8:F19)
A22: Oct 2026 | B22: Nov 2026 | C22: Dec 2026 | D22: Jan 2027 | E22: Feb 2027 | F22: Mar 2027 | G22: Apr 2027 | H22: May 2027 | I22: Jun 2027 | J22: Jul 2027 | K22: Aug 2027 | L22: Sep 2027 | M22: Daily Consumption | N22: LPG Dashboard | O22: Menu

Sheet LPG Dashboard
A5: LPG STORAGE — LIVE TANK MONITOR
A8: 3 LPG tanks • 5,000 L each • Enter tank level as %
A10: LPG TANK 1 | E10: LPG TANK 2 | I10: LPG TANK 3
A11: Capacity | B11: 4000 | C11: L | E11: Capacity | F11: 4000 | G11: L | I11: Capacity | J11: 4000 | K11: L
A12: REAL-TIME LEVEL | B12: 0 | C12: % | E12: REAL-TIME LEVEL | F12: 0 | G12: % | I12: REAL-TIME LEVEL | J12: 0 | K12: %
A13: Litres Available | B13: =B12*B11 | C13: L | E13: Litres Available | F13: =F12*F11 | G13: L | I13: Litres Available | J13: =J12*J11 | K13: L
A14: Remaining | B14: =MAX(0,B11-B13) | C14: L | E14: Remaining | F14: =MAX(0,F11-F13) | G14: L | I14: Remaining | J14: =MAX(0,J11-J13) | K14: L
A15: Status | B15: =IF(B12<=0.15,"CRITICAL",IF(B12<=0.3,"LOW",IF(B12<=0.6,"NORMAL","HIGH"))) | E15: Status | F15: =IF(F12<=0.15,"CRITICAL",IF(F12<=0.3,"LOW",IF(F12<=0.6,"NORMAL","HIGH"))) | I15: Status | J15: =IF(J12<=0.15,"CRITICAL",IF(J12<=0.3,"LOW",IF(J12<=0.6,"NORMAL","HIGH")))
A18: TANK 1 — LIVE LEVEL | E18: TANK 2 — LIVE LEVEL | I18: TANK 3 — LIVE LEVEL
A22: =TEXT($B$12,"0%") | E22: =TEXT($F$12,"0%") | I22: =TEXT($J$12,"0%")
A24: =TEXT($B$13,"#,##0")&" L / 5,000 L" | E24: =TEXT($F$13,"#,##0")&" L / 5,000 L" | I24: =TEXT($J$13,"#,##0")&" L / 5,000 L"
A25: =IF($B$12=0,"EMPTY",IF($B$12<=0.15,"REFILL REQUIRED",IF($B$12<=0.3,"LOW LEVEL",IF($B$12<=0.6,"NORMAL LEVEL","GOOD LEVEL")))) | E25: =IF($F$12=0,"EMPTY",IF($F$12<=0.15,"REFILL REQUIRED",IF($F$12<=0.3,"LOW LEVEL",IF($F$12<=0.6,"NORMAL LEVEL","GOOD LEVEL")))) | I25: =IF($J$12=0,"EMPTY",IF($J$12<=0.15,"REFILL REQUIRED",IF($J$12<=0.3,"LOW LEVEL",IF($J$12<=0.6,"NORMAL LEVEL","GOOD LEVEL"))))
A28: TOTAL LPG AVAILABLE
A29: =TEXT(SUM(B13,F13,J13),"#,##0")&" L / 15,000 L • "&TEXT(SUM(B13,F13,J13)/15000,"0%")&" AVAILABLE"

Sheet Oct 2026
A1: OCTOBER 2026 — DAILY CONSUMPTION
A3: Annual reporting cycle: 01 October 2026 → 30 September 2027
A5: Menu | B5: Dashboard | C5: Consumption | D5: LPG | E5: Oct 2026 | F5: Nov 2026 | G5: Dec 2026 | H5: Jan 2027 | I5: Feb 2027 | J5: Mar 2027 | K5: Apr 2027 | L5: May 2027 | M5: Jun 2027 | N5: Jul 2027 | O5: Aug 2027 | P5: Sep 2027
A7: Date | B7: Energy Consumption | C7: Water Consumption | D7: Gas Consumption | E7: Chilled Water Consumption | F7: Energy Unit | G7: Water Unit | H7: Gas Unit | I7: Chilled Water Unit | J7: Notes
A8: 46296 | B8: =SUMIF('Daily Consumption'!$B$6:$NB$6,$A8,'Daily Consumption'!$B$17:$NB$17) | C8: =SUMIF('Daily Consumption'!$B$6:$NB$6,$A8,'Daily Consumption'!$B$32:$NB$32) | D8: =SUMIF('Daily Consumption'!$B$6:$NB$6,$A8,'Daily Consumption'!$B$46:$NB$46) | E8: =SUMIF('Daily Consumption'!$B$6:$NB$6,$A8,'Daily Consumption'!$B$106:$NB$106) | F8: kWh | G8: m³ | H8: L | I8: m³
A9: 46297 | B9: =SUMIF('Daily Consumption'!$B$6:$NB$6,$A9,'Daily Consumption'!$B$17:$NB$17) | C9: =SUMIF('Daily Consumption'!$B$6:$NB$6,$A9,'Daily Consumption'!$B$32:$NB$32) | D9: =SUMIF('Daily Consumption'!$B$6:$NB$6,$A9,'Daily Consumption'!$B$46:$NB$46) | E9: =SUMIF('Daily Consumption'!$B$6:$NB$6,$A9,'Daily Consumption'!$B$106:$NB$106) | F9: kWh | G9: m³ | H9: L | I9: m³
A10: 46298 | B10: =SUMIF('Daily Consumption'!$B$6:$NB$6,$A10,'Daily Consumption'!$B$17:$NB$17) | C10: =SUMIF('Daily Consumption'!$B$6:$NB$6,$A10,'Daily Consumption'!$B$32:$NB$32) | D10: =SUMIF('Daily Consumption'!$B$6:$NB$6,$A10,'Daily Consumption'!$B$46:$NB$46) | E10: =SUMIF('Daily Consumption'!$B$6:$NB$6,$A10,'Daily Consumption'!$B$106:$NB$106) | F10: kWh | G10: m³ | H10: L | I10: m³
A11: 46299 | B11: =SUMIF('Daily Consumption'!$B$6:$NB$6,$A11,'Daily Consumption'!$B$17:$NB$17) | C11: =SUMIF('Daily Consumption'!$B$6:$NB$6,$A11,'Daily Consumption'!$B$32:$NB$32) | D11: =SUMIF('Daily Consumption'!$B$6:$NB$6,$A11,'Daily Consumption'!$B$46:$NB$46) | E11: =SUMIF('Daily Consumption'!$B$6:$NB$6,$A11,'Daily Consumption'!$B$106:$NB$106) | F11: kWh | G11: m³ | H11: L | I11: m³
A12: 46300 | B12: =SUMIF('Daily Consumption'!$B$6:$NB$6,$A12,'Daily Consumption'!$B$17:$NB$17) | C12: =SUMIF('Daily Consumption'!$B$6:$NB$6,$A12,'Daily Consumption'!$B$32:$NB$32) | D12: =SUMIF('Daily Consumption'!$B$6:$NB$6,$A12,'Daily Consumption'!$B$46:$NB$46) | E12: =SUMIF('Daily Consumption'!$B$6:$NB$6,$A12,'Daily Consumption'!$B$106:$NB$106) | F12: kWh | G12: m³ | H12: L | I12: m³
A13: 46301 | B13: =SUMIF('Daily Consumption'!$B$6:$NB$6,$A13,'Daily Consumption'!$B$17:$NB$17) | C13: =SUMIF('Daily Consumption'!$B$6:$NB$6,$A13,'Daily Consumption'!$B$32:$NB$32) | D13: =SUMIF('Daily Consumption'!$B$6:$NB$6,$A13,'Daily Consumption'!$B$46:$NB$46) | E13: =SUMIF('Daily Consumption'!$B$6:$NB$6,$A13,'Daily Consumption'!$B$106:$NB$106) | F13: kWh | G13: m³ | H13: L | I13: m³
A14: 46302 | B14: =SUMIF('Daily Consumption'!$B$6:$NB$6,$A14,'Daily Consumption'!$B$17:$NB$17) | C14: =SUMIF('Daily Consumption'!$B$6:$NB$6,$A14,'Daily Consumption'!$B$32:$NB$32) | D14: =SUMIF('Daily Consumption'!$B$6:$NB$6,$A14,'Daily Consumption'!$B$46:$NB$46) | E14: =SUMIF('Daily Consumption'!$B$6:$NB$6,$A14,'Daily Consumption'!$B$106:$NB$106) | F14: kWh | G14: m³ | H14: L | I14: m³
A15: 46303 | B15: =SUMIF('Daily Consumption'!$B$6:$NB$6,$A15,'Daily Consumption'!$B$17:$NB$17) | C15: =SUMIF('Daily Consumption'!$B$6:$NB$6,$A15,'Daily Consumption'!$B$32:$NB$32) | D15: =SUMIF('Daily Consumption'!$B$6:$NB$6,$A15,'Daily Consumption'!$B$46:$NB$46) | E15: =SUMIF('Daily Consumption'!$B$6:$NB$6,$A15,'Daily Consumption'!$B$106:$NB$106) | F15: kWh | G15: m³ | H15: L | I15: m³
A16: 46304 | B16: =SUMIF('Daily Consumption'!$B$6:$NB$6,$A16,'Daily Consumption'!$B$17:$NB$17) | C16: =SUMIF('Daily Consumption'!$B$6:$NB$6,$A16,'Daily Consumption'!$B$32:$NB$32) | D16: =SUMIF('Daily Consumption'!$B$6:$NB$6,$A16,'Daily Consumption'!$B$46:$NB$46) | E16: =SUMIF('Daily Consumption'!$B$6:$NB$6,$A16,'Daily Consumption'!$B$106:$NB$106) | F16: kWh | G16: m³ | H16: L | I16: m³
A17: 46305 | B17: =SUMIF('Daily Consumption'!$B$6:$NB$6,$A17,'Daily Consumption'!$B$17:$NB$17) | C17: =SUMIF('Daily Consumption'!$B$6:$NB$6,$A17,'Daily Consumption'!$B$32:$NB$32) | D17: =SUMIF('Daily Consumption'!$B$6:$NB$6,$A17,'Daily Consumption'!$B$46:$NB$46) | E17: =SUMIF('Daily Consumption'!$B$6:$NB$6,$A17,'Daily Consumption'!$B$106:$NB$106) | F17: kWh | G17: m³ | H17: L | I17: m³
A18: 46306 | B18: =SUMIF('Daily Consumption'!$B$6:$NB$6,$A18,'Daily Consumption'!$B$17:$NB$17) | C18: =SUMIF('Daily Consumption'!$B$6:$NB$6,$A18,'Daily Consumption'!$B$32:$NB$32) | D18: =SUMIF('Daily Consumption'!$B$6:$NB$6,$A18,'Daily Consumption'!$B$46:$NB$46) | E18: =SUMIF('Daily Consumption'!$B$6:$NB$6,$A18,'Daily Consumption'!$B$106:$NB$106) | F18: kWh | G18: m³ | H18: L | I18: m³
A19: 46307 | B19: =SUMIF('Daily Consumption'!$B$6:$NB$6,$A19,'Daily Consumption'!$B$17:$NB$17) | C19: =SUMIF('Daily Consumption'!$B$6:$NB$6,$A19,'Daily Consumption'!$B$32:$NB$32) | D19: =SUMIF('Daily Consumption'!$B$6:$NB$6,$A19,'Daily Consumption'!$B$46:$NB$46) | E19: =SUMIF('Daily Consumption'!$B$6:$NB$6,$A19,'Daily Consumption'!$B$106:$NB$106) | F19: kWh | G19: m³ | H19: L | I19: m³
... A38: 46326 | B38: =SUMIF('Daily Consumption'!$B$6:$NB$6,$A38,'Daily Consumption'!$B$17:$NB$17) | C38: =SUMIF('Daily Consumption'!$B$6:$NB$6,$A38,'Daily Consumption'!$B$32:$NB$32) | D38: =SUMIF('Daily Consumption'!$B$6:$NB$6,$A38,'Daily Consumption'!$B$46:$NB$46) | E38: =SUMIF('Daily Consumption'!$B$6:$NB$6,$A38,'Daily Consumption'!$B$106:$NB$106) | F38: kWh | G38: m³ | H38: L | I38: m³
A39: MONTH TOTAL | B39: =SUM(B8:B38) | C39: =SUM(C8:C38) | D39: =SUM(D8:D38) | E39: =SUM(E8:E38)

Sheet Nov 2026
A1: NOVEMBER 2026 — DAILY CONSUMPTION
A3: Annual reporting cycle: 01 October 2026 → 30 September 2027
A5: Menu | B5: Dashboard | C5: Consumption | D5: LPG | E5: Oct 2026 | F5: Nov 2026 | G5: Dec 2026 | H5: Jan 2027 | I5: Feb 2027 | J5: Mar 2027 | K5: Apr 2027 | L5: May 2027 | M5: Jun 2027 | N5: Jul 2027 | O5: Aug 2027 | P5: Sep 2027
A7: Date | B7: Energy Consumption | C7: Water Consumption | D7: Gas Consumption | E7: Chilled Water Consumption | F7: Energy Unit | G7: Water Unit | H7: Gas Unit | I7: Chilled Water Unit | J7: Notes
A8: 46327 | B8: =SUMIF('Daily Consumption'!$B$6:$NB$6,$A8,'Daily Consumption'!$B$17:$NB$17) | C8: =SUMIF('Daily Consumption'!$B$6:$NB$6,$A8,'Daily Consumption'!$B$32:$NB$32) | D8: =SUMIF('Daily Consumption'!$B$6:$NB$6,$A8,'Daily Consumption'!$B$46:$NB$46) | E8: =SUMIF('Daily Consumption'!$B$6:$NB$6,$A8,'Daily Consumption'!$B$106:$NB$106) | F8: kWh | G8: m³ | H8: L | I8: m³
A9: 46328 | B9: =SUMIF('Daily Consumption'!$B$6:$NB$6,$A9,'Daily Consumption'!$B$17:$NB$17) | C9: =SUMIF('Daily Consumption'!$B$6:$NB$6,$A9,'Daily Consumption'!$B$32:$NB$32) | D9: =SUMIF('Daily Consumption'!$B$6:$NB$6,$A9,'Daily Consumption'!$B$46:$NB$46) | E9: =SUMIF('Daily Consumption'!$B$6:$NB$6,$A9,'Daily Consumption'!$B$106:$NB$106) | F9: kWh | G9: m³ | H9: L | I9: m³
A10: 46329 | B10: =SUMIF('Daily Consumption'!$B$6:$NB$6,$A10,'Daily Consumption'!$B$17:$NB$17) | C10: =SUMIF('Daily Consumption'!$B$6:$NB$6,$A10,'Daily Consumption'!$B$32:$NB$32) | D10: =SUMIF('Daily Consumption'!$B$6:$NB$6,$A10,'Daily Consumption'!$B$46:$NB$46) | E10: =SUMIF('Daily Consumption'!$B$6:$NB$6,$A10,'Daily Consumption'!$B$106:$NB$106) | F10: kWh | G10: m³ | H10: L | I10: m³
A11: 46330 | B11: =SUMIF('Daily Consumption'!$B$6:$NB$6,$A11,'Daily Consumption'!$B$17:$NB$17) | C11: =SUMIF('Daily Consumption'!$B$6:$NB$6,$A11,'Daily Consumption'!$B$32:$NB$32) | D11: =SUMIF('Daily Consumption'!$B$6:$NB$6,$A11,'Daily Consumption'!$B$46:$NB$46) | E11: =SUMIF('Daily Consumption'!$B$6:$NB$6,$A11,'Daily Consumption'!$B$106:$NB$106) | F11: kWh | G11: m³ | H11: L | I11: m³
A12: 46331 | B12: =SUMIF('Daily Consumption'!$B$6:$NB$6,$A12,'Daily Consumption'!$B$17:$NB$17) | C12: =SUMIF('Daily Consumption'!$B$6:$NB$6,$A12,'Daily Consumption'!$B$32:$NB$32) | D12: =SUMIF('Daily Consumption'!$B$6:$NB$6,$A12,'Daily Consumption'!$B$46:$NB$46) | E12: =SUMIF('Daily Consumption'!$B$6:$NB$6,$A12,'Daily Consumption'!$B$106:$NB$106) | F12: kWh | G12: m³ | H12: L | I12: m³
A13: 46332 | B13: =SUMIF('Daily Consumption'!$B$6:$NB$6,$A13,'Daily Consumption'!$B$17:$NB$17) | C13: =SUMIF('Daily Consumption'!$B$6:$NB$6,$A13,'Daily Consumption'!$B$32:$NB$32) | D13: =SUMIF('Daily Consumption'!$B$6:$NB$6,$A13,'Daily Consumption'!$B$46:$NB$46) | E13: =SUMIF('Daily Consumption'!$B$6:$NB$6,$A13,'Daily Consumption'!$B$106:$NB$106) | F13: kWh | G13: m³ | H13: L | I13: m³
A14: 46333 | B14: =SUMIF('Daily Consumption'!$B$6:$NB$6,$A14,'Daily Consumption'!$B$17:$NB$17) | C14: =SUMIF('Daily Consumption'!$B$6:$NB$6,$A14,'Daily Consumption'!$B$32:$NB$32) | D14: =SUMIF('Daily Consumption'!$B$6:$NB$6,$A14,'Daily Consumption'!$B$46:$NB$46) | E14: =SUMIF('Daily Consumption'!$B$6:$NB$6,$A14,'Daily Consumption'!$B$106:$NB$106) | F14: kWh | G14: m³ | H14: L | I14: m³
A15: 46334 | B15: =SUMIF('Daily Consumption'!$B$6:$NB$6,$A15,'Daily Consumption'!$B$17:$NB$17) | C15: =SUMIF('Daily Consumption'!$B$6:$NB$6,$A15,'Daily Consumption'!$B$32:$NB$32) | D15: =SUMIF('Daily Consumption'!$B$6:$NB$6,$A15,'Daily Consumption'!$B$46:$NB$46) | E15: =SUMIF('Daily Consumption'!$B$6:$NB$6,$A15,'Daily Consumption'!$B$106:$NB$106) | F15: kWh | G15: m³ | H15: L | I15: m³
A16: 46335 | B16: =SUMIF('Daily Consumption'!$B$6:$NB$6,$A16,'Daily Consumption'!$B$17:$NB$17) | C16: =SUMIF('Daily Consumption'!$B$6:$NB$6,$A16,'Daily Consumption'!$B$32:$NB$32) | D16: =SUMIF('Daily Consumption'!$B$6:$NB$6,$A16,'Daily Consumption'!$B$46:$NB$46) | E16: =SUMIF('Daily Consumption'!$B$6:$NB$6,$A16,'Daily Consumption'!$B$106:$NB$106) | F16: kWh | G16: m³ | H16: L | I16: m³
A17: 46336 | B17: =SUMIF('Daily Consumption'!$B$6:$NB$6,$A17,'Daily Consumption'!$B$17:$NB$17) | C17: =SUMIF('Daily Consumption'!$B$6:$NB$6,$A17,'Daily Consumption'!$B$32:$NB$32) | D17: =SUMIF('Daily Consumption'!$B$6:$NB$6,$A17,'Daily Consumption'!$B$46:$NB$46) | E17: =SUMIF('Daily Consumption'!$B$6:$NB$6,$A17,'Daily Consumption'!$B$106:$NB$106) | F17: kWh | G17: m³ | H17: L | I17: m³
A18: 46337 | B18: =SUMIF('Daily Consumption'!$B$6:$NB$6,$A18,'Daily Consumption'!$B$17:$NB$17) | C18: =SUMIF('Daily Consumption'!$B$6:$NB$6,$A18,'Daily Consumption'!$B$32:$NB$32) | D18: =SUMIF('Daily Consumption'!$B$6:$NB$6,$A18,'Daily Consumption'!$B$46:$NB$46) | E18: =SUMIF('Daily Consumption'!$B$6:$NB$6,$A18,'Daily Consumption'!$B$106:$NB$106) | F18: kWh | G18: m³ | H18: L | I18: m³
A19: 46338 | B19: =SUMIF('Daily Consumption'!$B$6:$NB$6,$A19,'Daily Consumption'!$B$17:$NB$17) | C19: =SUMIF('Daily Consumption'!$B$6:$NB$6,$A19,'Daily Consumption'!$B$32:$NB$32) | D19: =SUMIF('Daily Consumption'!$B$6:$NB$6,$A19,'Daily Consumption'!$B$46:$NB$46) | E19: =SUMIF('Daily Consumption'!$B$6:$NB$6,$A19,'Daily Consumption'!$B$106:$NB$106) | F19: kWh | G19: m³ | H19: L | I19: m³
... A37: 46356 | B37: =SUMIF('Daily Consumption'!$B$6:$NB$6,$A37,'Daily Consumption'!$B$17:$NB$17) | C37: =SUMIF('Daily Consumption'!$B$6:$NB$6,$A37,'Daily Consumption'!$B$32:$NB$32) | D37: =SUMIF('Daily Consumption'!$B$6:$NB$6,$A37,'Daily Consumption'!$B$46:$NB$46) | E37: =SUMIF('Daily Consumption'!$B$6:$NB$6,$A37,'Daily Consumption'!$B$106:$NB$106) | F37: kWh | G37: m³ | H37: L | I37: m³
A38: MONTH TOTAL | B38: =SUM(B8:B37) | C38: =SUM(C8:C37) | D38: =SUM(D8:D37) | E38: =SUM(E8:E37)
A39: MONTH TOTAL | B39: =SUM(B8:B37) | C39: =SUM(C8:C37) | D39: =SUM(D8:D37) | E39: =SUM(E8:E37)

Sheet Dec 2026
A1: DECEMBER 2026 — DAILY CONSUMPTION
A3: Annual reporting cycle: 01 October 2026 → 30 September 2027
A5: Menu | B5: Dashboard | C5: Consumption | D5: LPG | E5: Oct 2026 | F5: Nov 2026 | G5: Dec 2026 | H5: Jan 2027 | I5: Feb 2027 | J5: Mar 2027 | K5: Apr 2027 | L5: May 2027 | M5: Jun 2027 | N5: Jul 2027 | O5: Aug 2027 | P5: Sep 2027
A7: Date | B7: Energy Consumption | C7: Water Consumption | D7: Gas Consumption | E7: Chilled Water Consumption | F7: Energy Unit | G7: Water Unit | H7: Gas Unit | I7: Chilled Water Unit | J7: Notes
A8: 46357 | B8: =SUMIF('Daily Consumption'!$B$6:$NB$6,$A8,'Daily Consumption'!$B$17:$NB$17) | C8: =SUMIF('Daily Consumption'!$B$6:$NB$6,$A8,'Daily Consumption'!$B$32:$NB$32) | D8: =SUMIF('Daily Consumption'!$B$6:$NB$6,$A8,'Daily Consumption'!$B$46:$NB$46) | E8: =SUMIF('Daily Consumption'!$B$6:$NB$6,$A8,'Daily Consumption'!$B$106:$NB$106) | F8: kWh | G8: m³ | H8: L | I8: m³
A9: 46358 | B9: =SUMIF('Daily Consumption'!$B$6:$NB$6,$A9,'Daily Consumption'!$B$17:$NB$17) | C9: =SUMIF('Daily Consumption'!$B$6:$NB$6,$A9,'Daily Consumption'!$B$32:$NB$32) | D9: =SUMIF('Daily Consumption'!$B$6:$NB$6,$A9,'Daily Consumption'!$B$46:$NB$46) | E9: =SUMIF('Daily Consumption'!$B$6:$NB$6,$A9,'Daily Consumption'!$B$106:$NB$106) | F9: kWh | G9: m³ | H9: L | I9: m³
A10: 46359 | B10: =SUMIF('Daily Consumption'!$B$6:$NB$6,$A10,'Daily Consumption'!$B$17:$NB$17) | C10: =SUMIF('Daily Consumption'!$B$6:$NB$6,$A10,'Daily Consumption'!$B$32:$NB$32) | D10: =SUMIF('Daily Consumption'!$B$6:$NB$6,$A10,'Daily Consumption'!$B$46:$NB$46) | E10: =SUMIF('Daily Consumption'!$B$6:$NB$6,$A10,'Daily Consumption'!$B$106:$NB$106) | F10: kWh | G10: m³ | H10: L | I10: m³
A11: 46360 | B11: =SUMIF('Daily Consumption'!$B$6:$NB$6,$A11,'Daily Consumption'!$B$17:$NB$17) | C11: =SUMIF('Daily Consumption'!$B$6:$NB$6,$A11,'Daily Consumption'!$B$32:$NB$32) | D11: =SUMIF('Daily Consumption'!$B$6:$NB$6,$A11,'Daily Consumption'!$B$46:$NB$46) | E11: =SUMIF('Daily Consumption'!$B$6:$NB$6,$A11,'Daily Consumption'!$B$106:$NB$106) | F11: kWh | G11: m³ | H11: L | I11: m³
A12: 46361 | B12: =SUMIF('Daily Consumption'!$B$6:$NB$6,$A12,'Daily Consumption'!$B$17:$NB$17) | C12: =SUMIF('Daily Consumption'!$B$6:$NB$6,$A12,'Daily Consumption'!$B$32:$NB$32) | D12: =SUMIF('Daily Consumption'!$B$6:$NB$6,$A12,'Daily Consumption'!$B$46:$NB$46) | E12: =SUMIF('Daily Consumption'!$B$6:$NB$6,$A12,'Daily Consumption'!$B$106:$NB$106) | F12: kWh | G12: m³ | H12: L | I12: m³
A13: 46362 | B13: =SUMIF('Daily Consumption'!$B$6:$NB$6,$A13,'Daily Consumption'!$B$17:$NB$17) | C13: =SUMIF('Daily Consumption'!$B$6:$NB$6,$A13,'Daily Consumption'!$B$32:$NB$32) | D13: =SUMIF('Daily Consumption'!$B$6:$NB$6,$A13,'Daily Consumption'!$B$46:$NB$46) | E13: =SUMIF('Daily Consumption'!$B$6:$NB$6,$A13,'Daily Consumption'!$B$106:$NB$106) | F13: kWh | G13: m³ | H13: L | I13: m³
A14: 46363 | B14: =SUMIF('Daily Consumption'!$B$6:$NB$6,$A14,'Daily Consumption'!$B$17:$NB$17) | C14: =SUMIF('Daily Consumption'!$B$6:$NB$6,$A14,'Daily Consumption'!$B$32:$NB$32) | D14: =SUMIF('Daily Consumption'!$B$6:$NB$6,$A14,'Daily Consumption'!$B$46:$NB$46) | E14: =SUMIF('Daily Consumption'!$B$6:$NB$6,$A14,'Daily Consumption'!$B$106:$NB$106) | F14: kWh | G14: m³ | H14: L | I14: m³
A15: 46364 | B15: =SUMIF('Daily Consumption'!$B$6:$NB$6,$A15,'Daily Consumption'!$B$17:$NB$17) | C15: =SUMIF('Daily Consumption'!$B$6:$NB$6,$A15,'Daily Consumption'!$B$32:$NB$32) | D15: =SUMIF('Daily Consumption'!$B$6:$NB$6,$A15,'Daily Consumption'!$B$46:$NB$46) | E15: =SUMIF('Daily Consumption'!$B$6:$NB$6,$A15,'Daily Consumption'!$B$106:$NB$106) | F15: kWh | G15: m³ | H15: L | I15: m³
A16: 46365 | B16: =SUMIF('Daily Consumption'!$B$6:$NB$6,$A16,'Daily Consumption'!$B$17:$NB$17) | C16: =SUMIF('Daily Consumption'!$B$6:$NB$6,$A16,'Daily Consumption'!$B$32:$NB$32) | D16: =SUMIF('Daily Consumption'!$B$6:$NB$6,$A16,'Daily Consumption'!$B$46:$NB$46) | E16: =SUMIF('Daily Consumption'!$B$6:$NB$6,$A16,'Daily Consumption'!$B$106:$NB$106) | F16: kWh | G16: m³ | H16: L | I16: m³
A17: 46366 | B17: =SUMIF('Daily Consumption'!$B$6:$NB$6,$A17,'Daily Consumption'!$B$17:$NB$17) | C17: =SUMIF('Daily Consumption'!$B$6:$NB$6,$A17,'Daily Consumption'!$B$32:$NB$32) | D17: =SUMIF('Daily Consumption'!$B$6:$NB$6,$A17,'Daily Consumption'!$B$46:$NB$46) | E17: =SUMIF('Daily Consumption'!$B$6:$NB$6,$A17,'Daily Consumption'!$B$106:$NB$106) | F17: kWh | G17: m³ | H17: L | I17: m³
A18: 46367 | B18: =SUMIF('Daily Consumption'!$B$6:$NB$6,$A18,'Daily Consumption'!$B$17:$NB$17) | C18: =SUMIF('Daily Consumption'!$B$6:$NB$6,$A18,'Daily Consumption'!$B$32:$NB$32) | D18: =SUMIF('Daily Consumption'!$B$6:$NB$6,$A18,'Daily Consumption'!$B$46:$NB$46) | E18: =SUMIF('Daily Consumption'!$B$6:$NB$6,$A18,'Daily Consumption'!$B$106:$NB$106) | F18: kWh | G18: m³ | H18: L | I18: m³
A19: 46368 | B19: =SUMIF('Daily Consumption'!$B$6:$NB$6,$A19,'Daily Consumption'!$B$17:$NB$17) | C19: =SUMIF('Daily Consumption'!$B$6:$NB$6,$A19,'Daily Consumption'!$B$32:$NB$32) | D19: =SUMIF('Daily Consumption'!$B$6:$NB$6,$A19,'Daily Consumption'!$B$46:$NB$46) | E19: =SUMIF('Daily Consumption'!$B$6:$NB$6,$A19,'Daily Consumption'!$B$106:$NB$106) | F19: kWh | G19: m³ | H19: L | I19: m³
